Workbook
Name Analyst: Internal!$D$28:$H$28
Name Developer: Internal!$D$29:$I$29
Name Manager: Internal!$D$27:$I$27
Name Operator: Internal!$D$31:$J$31
Name Other: Internal!$D$32
Name Student: Internal!$D$26:$G$26
Name Tester: Internal!$D$30:$I$30

Sheet Copyright
B2: Copyright
B4: # Planning-Template.xlsx Copyright (C) 2012-2026 Rafael Corchuelo. In keeping with the traditional purpose of furthering education and research, it is the policy of the copyright owner to permit non-commercial use and redistribution of this software. It has been tested carefully, but it is not guaranteed for any particular purposes. The copyright owner does not offer any warranties or representations, nor do they accept any liabilities with respect to them.

Sheet Abstract
B2: Abstract
B4: This spreadsheet is intended to facilitate planning on the tasks of your project. Please, share it in your workgroup and closely follow the methodology taught.
C8: Help comments
C9: Enter configuration data in these cells
C10: Warning and error messages.
C11: Data computed automatically. Do not change them.
C12: Internal data. Do not change them.

Sheet D01
C2: Deliverable D01
C4: Use this form to document the tasks that you perform in your projects. Please, review the colour code in the "Abstract" sheet. In the exceptional case that you need to perform more tasks than expected, add them at the end.
C6: Costs | D6: Expected: | E6: =SUM(N11:N110) -> 977.5
D7: Actual: | E7: =SUM(O11:O110) -> 0
I9: Execution period | L9: Workload (in hours) | N9: Costs (in EUR)
B10: ORDER | C10: ID | D10: Type | E10: Assignee | F10: Role | G10: Activity | H10: Parent | I10: Start moment | J10: End moment | K10: Status | L10: Expected | M10: Actual | N10: Expected | O10: Actual | P10: Description
B11: 1 | C11: =IF(ISBLANK(D11),"",_xlfn.CONCAT("T",TEXT(B11,"0000"),"/",VLOOKUP(D11,Internal!$B$35:C$39,2,FALSE),IF(OR(D11="QA",D11="Revision"),_xlfn.CONCAT("/",H11),""))) -> T0001/M | D11: Management | E11: Student 1 | F11: Manager | G11: Make plans | I11: 46059.667 | J11: 46059.75 | K11: =IF(OR(I11="",J11=""),"",IF(AND(J11<>"",I11>=NOW()),"Planned",IF(AND(J11<>"",J11<NOW()),"Completed","Ongoing"))) -> Ongoing | L11: 1.5 | N11: =IF(ISBLANK(L11),"",L11*VLOOKUP($F11,Internal!$B$26:$C$32,2,FALSE)) -> 75 | O11: =IF(ISBLANK(M11),"",M11*VLOOKUP($F11,Internal!$B$26:$C$32,2,FALSE)) | P11: Planning report
B12: 2 | C12: =IF(ISBLANK(D12),"",_xlfn.CONCAT("T",TEXT(B12,"0000"),"/",VLOOKUP(D12,Internal!$B$35:C$39,2,FALSE),IF(OR(D12="QA",D12="Revision"),_xlfn.CONCAT("/",H12),""))) -> T0002/O | D12: Other | E12: ALL | F12: Student | G12: Attend lecture | I12: 46048.444 | J12: 46048.521 | K12: =IF(OR(I12="",J12=""),"",IF(AND(J12<>"",I12>=NOW()),"Planned",IF(AND(J12<>"",J12<NOW()),"Completed","Ongoing"))) -> Completed | L12: 1.83 | M12: 1.83 | N12: =IF(ISBLANK(L12),"",L12*VLOOKUP($F12,Internal!$B$26:$C$32,2,FALSE)) -> 0 | O12: =IF(ISBLANK(M12),"",M12*VLOOKUP($F12,Internal!$B$26:$C$32,2,FALSE)) -> 0 | P12: L01 - Introduction | S01 - The Subject
B13: 3 | C13: =IF(ISBLANK(D13),"",_xlfn.CONCAT("T",TEXT(B13,"0000"),"/",VLOOKUP(D13,Internal!$B$35:C$39,2,FALSE),IF(OR(D13="QA",D13="Revision"),_xlfn.CONCAT("/",H13),""))) -> T0003/O | D13: Other | E13: ALL | F13: Student | G13: Attend lecture | I13: 46051.354 | J13: 46051.444 | K13: =IF(OR(I13="",J13=""),"",IF(AND(J13<>"",I13>=NOW()),"Planned",IF(AND(J13<>"",J13<NOW()),"Completed","Ongoing"))) -> Completed | L13: 1.83 | M13: 1.83 | N13: =IF(ISBLANK(L13),"",L13*VLOOKUP($F13,Internal!$B$26:$C$32,2,FALSE)) -> 0 | O13: =IF(ISBLANK(M13),"",M13*VLOOKUP($F13,Internal!$B$26:$C$32,2,FALSE)) -> 0 | P13: L01 - Introduction | S02 - Working together
B14: 4 | C14: =IF(ISBLANK(D14),"",_xlfn.CONCAT("T",TEXT(B14,"0000"),"/",VLOOKUP(D14,Internal!$B$35:C$39,2,FALSE),IF(OR(D14="QA",D14="Revision"),_xlfn.CONCAT("/",H14),""))) -> T0004/O | D14: Other | E14: ALL | F14: Student | G14: Attend lecture | I14: 46055.444 | J14: 46055.521 | K14: =IF(OR(I14="",J14=""),"",IF(AND(J14<>"",I14>=NOW()),"Planned",IF(AND(J14<>"",J14<NOW()),"Completed","Ongoing"))) -> Completed | L14: 1.83 | M14: 1.83 | N14: =IF(ISBLANK(L14),"",L14*VLOOKUP($F14,Internal!$B$26:$C$32,2,FALSE)) -> 0 | O14: =IF(ISBLANK(M14),"",M14*VLOOKUP($F14,Internal!$B$26:$C$32,2,FALSE)) -> 0 | P14: L01 - Introduction | S03 - Getting started
B15: 5 | C15: =IF(ISBLANK(D15),"",_xlfn.CONCAT("T",TEXT(B15,"0000"),"/",VLOOKUP(D15,Internal!$B$35:C$39,2,FALSE),IF(OR(D15="QA",D15="Revision"),_xlfn.CONCAT("/",H15),""))) -> T0005/O | D15: Other | E15: ALL | F15: Student | G15: Attend lecture | I15: 46058.354 | J15: 46058.444 | K15: =IF(OR(I15="",J15=""),"",IF(AND(J15<>"",I15>=NOW()),"Planned",IF(AND(J15<>"",J15<NOW()),"Completed","Ongoing"))) -> Completed | L15: 1.83 | N15: =IF(ISBLANK(L15),"",L15*VLOOKUP($F15,Internal!$B$26:$C$32,2,FALSE)) -> 0 | O15: =IF(ISBLANK(M15),"",M15*VLOOKUP($F15,Internal!$B$26:$C$32,2,FALSE)) | P15: L01 - Introduction | S04 - The Framework
B16: 6 | C16: =IF(ISBLANK(D16),"",_xlfn.CONCAT("T",TEXT(B16,"0000"),"/",VLOOKUP(D16,Internal!$B$35:C$39,2,FALSE),IF(OR(D16="QA",D16="Revision"),_xlfn.CONCAT("/",H16),""))) -> T0006/O | D16: Other | E16: ALL | F16: Student | G16: Attend lecture | I16: 46062.444 | J16: 46062.521 | K16: =IF(OR(I16="",J16=""),"",IF(AND(J16<>"",I16>=NOW()),"Planned",IF(AND(J16<>"",J16<NOW()),"Completed","Ongoing"))) -> Planned | L16: 1.83 | N16: =IF(ISBLANK(L16),"",L16*VLOOKUP($F16,Internal!$B$26:$C$32,2,FALSE)) -> 0 | O16: =IF(ISBLANK(M16),"",M16*VLOOKUP($F16,Internal!$B$26:$C$32,2,FALSE)) | P16: Follow up
B17: 7 | C17: =IF(ISBLANK(D17),"",_xlfn.CONCAT("T",TEXT(B17,"0000"),"/",VLOOKUP(D17,Internal!$B$35:C$39,2,FALSE),IF(OR(D17="QA",D17="Revision"),_xlfn.CONCAT("/",H17),""))) -> T0007/O | D17: Other | E17: ALL | F17: Student | G17: Attend lecture | I17: 46065.354 | J17: 46065.444 | K17: =IF(OR(I17="",J17=""),"",IF(AND(J17<>"",I17>=NOW()),"Planned",IF(AND(J17<>"",J17<NOW()),"Completed","Ongoing"))) -> Planned | L17: 1.83 | N17: =IF(ISBLANK(L17),"",L17*VLOOKUP($F17,Internal!$B$26:$C$32,2,FALSE)) -> 0 | O17: =IF(ISBLANK(M17),"",M17*VLOOKUP($F17,Internal!$B$26:$C$32,2,FALSE)) | P17: L02 - The data model | S01 - Models and queries
B18: 8 | C18: =IF(ISBLANK(D18),"",_xlfn.CONCAT("T",TEXT(B18,"0000"),"/",VLOOKUP(D18,Internal!$B$35:C$39,2,FALSE),IF(OR(D18="QA",D18="Revision"),_xlfn.CONCAT("/",H18),""))) -> T0008/O | D18: Other | E18: ALL | F18: Student | G18: Attend lecture | I18: 46069.444 | J18: 46069.521 | K18: =IF(OR(I18="",J18=""),"",IF(AND(J18<>"",I18>=NOW()),"Planned",IF(AND(J18<>"",J18<NOW()),"Completed","Ongoing"))) -> Planned | L18: 1.83 | N18: =IF(ISBLANK(L18),"",L18*VLOOKUP($F18,Internal!$B$26:$C$32,2,FALSE)) -> 0 | O18: =IF(ISBLANK(M18),"",M18*VLOOKUP($F18,Internal!$B$26:$C$32,2,FALSE)) | P18: Follow up
B19: 9 | C19: =IF(ISBLANK(D19),"",_xlfn.CONCAT("T",TEXT(B19,"0000"),"/",VLOOKUP(D19,Internal!$B$35:C$39,2,FALSE),IF(OR(D19="QA",D19="Revision"),_xlfn.CONCAT("/",H19),""))) -> T0009/O | D19: Other | E19: ALL | F19: Student | G19: Attend lecture | I19: 46072.354 | J19: 46072.444 | K19: =IF(OR(I19="",J19=""),"",IF(AND(J19<>"",I19>=NOW()),"Planned",IF(AND(J19<>"",J19<NOW()),"Completed","Ongoing"))) -> Planned | L19: 1.83 | N19: =IF(ISBLANK(L19),"",L19*VLOOKUP($F19,Internal!$B$26:$C$32,2,FALSE)) -> 0 | O19: =IF(ISBLANK(M19),"",M19*VLOOKUP($F19,Internal!$B$26:$C$32,2,FALSE)) | P19: L02 - The data model | S02 - Validation and population
B20: 10 | C20: =IF(ISBLANK(D20),"",_xlfn.CONCAT("T",TEXT(B20,"0000"),"/",VLOOKUP(D20,Internal!$B$35:C$39,2,FALSE),IF(OR(D20="QA",D20="Revision"),_xlfn.CONCAT("/",H20),""))) -> T0010/O | D20: Other | E20: ALL | F20: Student | G20: Attend lecture | I20: 46076.444 | J20: 46076.521 | K20: =IF(OR(I20="",J20=""),"",IF(AND(J20<>"",I20>=NOW()),"Planned",IF(AND(J20<>"",J20<NOW()),"Completed","Ongoing"))) -> Planned | L20: 1.83 | N20: =IF(ISBLANK(L20),"",L20*VLOOKUP($F20,Internal!$B$26:$C$32,2,FALSE)) -> 0 | O20: =IF(ISBLANK(M20),"",M20*VLOOKUP($F20,Internal!$B$26:$C$32,2,FALSE)) | P20: Follow up
B21: 11 | C21: =IF(ISBLANK(D21),"",_xlfn.CONCAT("T",TEXT(B21,"0000"),"/",VLOOKUP(D21,Internal!$B$35:C$39,2,FALSE),IF(OR(D21="QA",D21="Revision"),_xlfn.CONCAT("/",H21),""))) -> T0011/O | D21: Other | E21: ALL | F21: Student | G21: Attend lecture | I21: 46079.354 | J21: 46079.444 | K21: =IF(OR(I21="",J21=""),"",IF(AND(J21<>"",I21>=NOW()),"Planned",IF(AND(J21<>"",J21<NOW()),"Completed","Ongoing"))) -> Planned | L21: 1.83 | N21: =IF(ISBLANK(L21),"",L21*VLOOKUP($F21,Internal!$B$26:$C$32,2,FALSE)) -> 0 | O21: =IF(ISBLANK(M21),"",M21*VLOOKUP($F21,Internal!$B$26:$C$32,2,FALSE)) | P21: L02 - The data model | S03 - Advanced topics
B22: 12 | C22: =IF(ISBLANK(D22),"",_xlfn.CONCAT("T",TEXT(B22,"0000"),"/",VLOOKUP(D22,Internal!$B$35:C$39,2,FALSE),IF(OR(D22="QA",D22="Revision"),_xlfn.CONCAT("/",H22),""))) -> T0012/O | D22: Other | E22: ALL | F22: Student | G22: Attend lecture | I22: 46083.444 | J22: 46083.521 | K22: =IF(OR(I22="",J22=""),"",IF(AND(J22<>"",I22>=NOW()),"Planned",IF(AND(J22<>"",J22<NOW()),"Completed","Ongoing"))) -> Planned | L22: 1.83 | N22: =IF(ISBLANK(L22),"",L22*VLOOKUP($F22,Internal!$B$26:$C$32,2,FALSE)) -> 0 | O22: =IF(ISBLANK(M22),"",M22*VLOOKUP($F22,Internal!$B$26:$C$32,2,FALSE)) | P22: Follow up
B23: 13 | C23: =IF(ISBLANK(D23),"",_xlfn.CONCAT("T",TEXT(B23,"0000"),"/",VLOOKUP(D23,Internal!$B$35:C$39,2,FALSE),IF(OR(D23="QA",D23="Revision"),_xlfn.CONCAT("/",H23),""))) -> T0013/O | D23: Other | E23: ALL | F23: Student | G23: Attend lecture | I23: 46086.354 | J23: 46086.444 | K23: =IF(OR(I23="",J23=""),"",IF(AND(J23<>"",I23>=NOW()),"Planned",IF(AND(J23<>"",J23<NOW()),"Completed","Ongoing"))) -> Planned | L23: 1.83 | N23: =IF(ISBLANK(L23),"",L23*VLOOKUP($F23,Internal!$B$26:$C$32,2,FALSE)) -> 0 | O23: =IF(ISBLANK(M23),"",M23*VLOOKUP($F23,Internal!$B$26:$C$32,2,FALSE)) | P23: L03 - Implementing features | S01 - Display features
B24: 14 | C24: =IF(ISBLANK(D24),"",_xlfn.CONCAT("T",TEXT(B24,"0000"),"/",VLOOKUP(D24,Internal!$B$35:C$39,2,FALSE),IF(OR(D24="QA",D24="Revision"),_xlfn.CONCAT("/",H24),""))) -> T0014/O | D24: Other | E24: ALL | F24: Student | G24: Attend lecture | I24: 46090.444 | J24: 46090.521 | K24: =IF(OR(I24="",J24=""),"",IF(AND(J24<>"",I24>=NOW()),"Planned",IF(AND(J24<>"",J24<NOW()),"Completed","Ongoing"))) -> Planned | L24: 1.83 | N24: =IF(ISBLANK(L24),"",L24*VLOOKUP($F24,Internal!$B$26:$C$32,2,FALSE)) -> 0 | O24: =IF(ISBLANK(M24),"",M24*VLOOKUP($F24,Internal!$B$26:$C$32,2,FALSE)) | P24: Follow up
B25: 15 | C25: =IF(ISBLANK(D25),"",_xlfn.CONCAT("T",TEXT(B25,"0000"),"/",VLOOKUP(D25,Internal!$B$35:C$39,2,FALSE),IF(OR(D25="QA",D25="Revision"),_xlfn.CONCAT("/",H25),""))) -> T0015/O | D25: Other | E25: ALL | F25: Student | G25: Attend lecture | I25: 46093.354 | J25: 46093.444 | K25: =IF(OR(I25="",J25=""),"",IF(AND(J25<>"",I25>=NOW()),"Planned",IF(AND(J25<>"",J25<NOW()),"Completed","Ongoing"))) -> Planned | L25: 1.83 | N25: =IF(ISBLANK(L25),"",L25*VLOOKUP($F25,Internal!$B$26:$C$32,2,FALSE)) -> 0 | O25: =IF(ISBLANK(M25),"",M25*VLOOKUP($F25,Internal!$B$26:$C$32,2,FALSE)) | P25: L03 - Implementing features | S02 - Edition features
B26: 16 | C26: =IF(ISBLANK(D26),"",_xlfn.CONCAT("T",TEXT(B26,"0000"),"/",VLOOKUP(D26,Internal!$B$35:C$39,2,FALSE),IF(OR(D26="QA",D26="Revision"),_xlfn.CONCAT("/",H26),""))) -> T0016/O | D26: Other | E26: ALL | F26: Student | G26: Attend lecture | I26: 46097.444 | J26: 46097.521 | K26: =IF(OR(I26="",J26=""),"",IF(AND(J26<>"",I26>=NOW()),"Planned",IF(AND(J26<>"",J26<NOW()),"Completed","Ongoing"))) -> Planned | L26: 1.83 | N26: =IF(ISBLANK(L26),"",L26*VLOOKUP($F26,Internal!$B$26:$C$32,2,FALSE)) -> 0 | O26: =IF(ISBLANK(M26),"",M26*VLOOKUP($F26,Internal!$B$26:$C$32,2,FALSE)) | P26: Follow up
... B39: 29 | C39: =IF(ISBLANK(D39),"",_xlfn.CONCAT("T",TEXT(B39,"0000"),"/",VLOOKUP(D39,Internal!$B$35:C$39,2,FALSE),IF(OR(D39="QA",D39="Revision"),_xlfn.CONCAT("/",H39),""))) -> T0029/D | D39: Development | E39: Student 1 | F39: Developer | G39: Implement feature | I39: 46061.833 | J39: 46068.833 | K39: =IF(OR(I39="",J39=""),"",IF(AND(J39<>"",I39>=NOW()),"Planned",IF(AND(J39<>"",J39<NOW()),"Completed","Ongoing"))) -> Planned | L39: 1 | N39: =IF(ISBLANK(L39),"",L39*VLOOKUP($F39,Internal!$B$26:$C$32,2,FALSE)) -> 25 | O39: =IF(ISBLANK(M39),"",M39*VLOOKUP($F39,Internal!$B$26:$C$32,2,FALSE)) | P39: Requisito de información: Implementar Model-C01.uxf
B40: 30 | C40: =IF(ISBLANK(D40),"",_xlfn.CONCAT("T",TEXT(B40,"0000"),"/",VLOOKUP(D40,Internal!$B$35:C$39,2,FALSE),IF(OR(D40="QA",D40="Revision"),_xlfn.CONCAT("/",H40),""))) -> T0030/R/T0029/D | D40: Revision | E40: Student 2 | F40: Tester | G40: Check task | H40: T0029/D | I40: 46061.833 | J40: 46068.833 | K40: =IF(OR(I40="",J40=""),"",IF(AND(J40<>"",I40>=NOW()),"Planned",IF(AND(J40<>"",J40<NOW()),"Completed","Ongoing"))) -> Planned | L40: 0.25 | N40: =IF(ISBLANK(L40),"",L40*VLOOKUP($F40,Internal!$B$26:$C$32,2,FALSE)) -> 7.5 | O40: =IF(ISBLANK(M40),"",M40*VLOOKUP($F40,Internal!$B$26:$C$32,2,FALSE))
B41: 31 | C41: =IF(ISBLANK(D41),"",_xlfn.CONCAT("T",TEXT(B41,"0000"),"/",VLOOKUP(D41,Internal!$B$35:C$39,2,FALSE),IF(OR(D41="QA",D41="Revision"),_xlfn.CONCAT("/",H41),""))) -> T0031/D | D41: Development | E41: Student 1 | F41: Developer | G41: Implement feature | I41: 46061.833 | J41: 46068.833 | K41: =IF(OR(I41="",J41=""),"",IF(AND(J41<>"",I41>=NOW()),"Planned",IF(AND(J41<>"",J41<NOW()),"Completed","Ongoing"))) -> Planned | L41: 1 | N41: =IF(ISBLANK(L41),"",L41*VLOOKUP($F41,Internal!$B$26:$C$32,2,FALSE)) -> 25 | O41: =IF(ISBLANK(M41),"",M41*VLOOKUP($F41,Internal!$B$26:$C$32,2,FALSE)) | P41: Funcional: Cualquier usuario podrá listar y mostrar invenciones publicadas y sus partes. Además, de poder ver el perfil del inventor
B42: 32 | C42: =IF(ISBLANK(D42),"",_xlfn.CONCAT("T",TEXT(B42,"0000"),"/",VLOOKUP(D42,Internal!$B$35:C$39,2,FALSE),IF(OR(D42="QA",D42="Revision"),_xlfn.CONCAT("/",H42),""))) -> T0032/R/T0031/D | D42: Revision | E42: Student 2 | F42: Tester | G42: Check task | H42: T0031/D | I42: 46061.833 | J42: 46068.833 | K42: =IF(OR(I42="",J42=""),"",IF(AND(J42<>"",I42>=NOW()),"Planned",IF(AND(J42<>"",J42<NOW()),"Completed","Ongoing"))) -> Planned | L42: 0.25 | N42: =IF(ISBLANK(L42),"",L42*VLOOKUP($F42,Internal!$B$26:$C$32,2,FALSE)) -> 7.5 | O42: =IF(ISBLANK(M42),"",M42*VLOOKUP($F42,Internal!$B$26:$C$32,2,FALSE))
B43: 33 | C43: =IF(ISBLANK(D43),"",_xlfn.CONCAT("T",TEXT(B43,"0000"),"/",VLOOKUP(D43,Internal!$B$35:C$39,2,FALSE),IF(OR(D43="QA",D43="Revision"),_xlfn.CONCAT("/",H43),""))) -> T0033/D | D43: Development | E43: Student 1 | F43: Developer | G43: Implement feature | I43: 46061.833 | J43: 46068.833 | K43: =IF(OR(I43="",J43=""),"",IF(AND(J43<>"",I43>=NOW()),"Planned",IF(AND(J43<>"",J43<NOW()),"Completed","Ongoing"))) -> Planned | L43: 1 | N43: =IF(ISBLANK(L43),"",L43*VLOOKUP($F43,Internal!$B$26:$C$32,2,FALSE)) -> 25 | O43: =IF(ISBLANK(M43),"",M43*VLOOKUP($F43,Internal!$B$26:$C$32,2,FALSE)) | P43: Funcional: Cualquier usuario autenticado podrá adquirir el rol de inventor y actualizar el rol del perfil
B44: 34 | C44: =IF(ISBLANK(D44),"",_xlfn.CONCAT("T",TEXT(B44,"0000"),"/",VLOOKUP(D44,Internal!$B$35:C$39,2,FALSE),IF(OR(D44="QA",D44="Revision"),_xlfn.CONCAT("/",H44),""))) -> T0034/R/T0033/D | D44: Revision | E44: Student 2 | F44: Tester | G44: Check task | H44: T0033/D | I44: 46061.833 | J44: 46068.833 | K44: =IF(OR(I44="",J44=""),"",IF(AND(J44<>"",I44>=NOW()),"Planned",IF(AND(J44<>"",J44<NOW()),"Completed","Ongoing"))) -> Planned | L44: 0.25 | N44: =IF(ISBLANK(L44),"",L44*VLOOKUP($F44,Internal!$B$26:$C$32,2,FALSE)) -> 7.5 | O44: =IF(ISBLANK(M44),"",M44*VLOOKUP($F44,Internal!$B$26:$C$32,2,FALSE))
B45: 35 | C45: =IF(ISBLANK(D45),"",_xlfn.CONCAT("T",TEXT(B45,"0000"),"/",VLOOKUP(D45,Internal!$B$35:C$39,2,FALSE),IF(OR(D45="QA",D45="Revision"),_xlfn.CONCAT("/",H45),""))) -> T0035/D | D45: Development | E45: Student 1 | F45: Developer | G45: Implement feature | I45: 46061.833 | J45: 46068.833 | K45: =IF(OR(I45="",J45=""),"",IF(AND(J45<>"",I45>=NOW()),"Planned",IF(AND(J45<>"",J45<NOW()),"Completed","Ongoing"))) -> Planned | L45: 1 | N45: =IF(ISBLANK(L45),"",L45*VLOOKUP($F45,Internal!$B$26:$C$32,2,FALSE)) -> 25 | O45: =IF(ISBLANK(M45),"",M45*VLOOKUP($F45,Internal!$B$26:$C$32,2,FALSE)) | P45: Funcional: Un usuario autenticado como inventor, CRUD sobre sus inventos y sus partes. Además, de poder publicar el invento, lo que haría que sus partes tambien se publicasen.
B46: 36 | C46: =IF(ISBLANK(D46),"",_xlfn.CONCAT("T",TEXT(B46,"0000"),"/",VLOOKUP(D46,Internal!$B$35:C$39,2,FALSE),IF(OR(D46="QA",D46="Revision"),_xlfn.CONCAT("/",H46),""))) -> T0036/R/T0035/D | D46: Revision | E46: Student 2 | F46: Tester | G46: Check task | H46: T0035/D | I46: 46061.833 | J46: 46068.833 | K46: =IF(OR(I46="",J46=""),"",IF(AND(J46<>"",I46>=NOW()),"Planned",IF(AND(J46<>"",J46<NOW()),"Completed","Ongoing"))) -> Planned | L46: 0.25 | N46: =IF(ISBLANK(L46),"",L46*VLOOKUP($F46,Internal!$B$26:$C$32,2,FALSE)) -> 7.5 | O46: =IF(ISBLANK(M46),"",M46*VLOOKUP($F46,Internal!$B$26:$C$32,2,FALSE))
B47: 37 | C47: =IF(ISBLANK(D47),"",_xlfn.CONCAT("T",TEXT(B47,"0000"),"/",VLOOKUP(D47,Internal!$B$35:C$39,2,FALSE),IF(OR(D47="QA",D47="Revision"),_xlfn.CONCAT("/",H47),""))) -> T0037/D | D47: Development | E47: Student 1 | F47: Developer | G47: Implement feature | I47: 46061.833 | J47: 46068.833 | K47: =IF(OR(I47="",J47=""),"",IF(AND(J47<>"",I47>=NOW()),"Planned",IF(AND(J47<>"",J47<NOW()),"Completed","Ongoing"))) -> Planned | N47: =IF(ISBLANK(L47),"",L47*VLOOKUP($F47,Internal!$B$26:$C$32,2,FALSE)) | O47: =IF(ISBLANK(M47),"",M47*VLOOKUP($F47,Internal!$B$26:$C$32,2,FALSE)) | P47: No funcional: La interfaz de usuario deberá estar disponible en inglés y español; incluyendo boolean, fechas, dinero y valores numericos
B48: 38 | C48: =IF(ISBLANK(D48),"",_xlfn.CONCAT("T",TEXT(B48,"0000"),"/",VLOOKUP(D48,Internal!$B$35:C$39,2,FALSE),IF(OR(D48="QA",D48="Revision"),_xlfn.CONCAT("/",H48),""))) -> T0038/R/T0037/D | D48: Revision | E48: Student 2 | F48: Tester | G48: Check task | H48: T0037/D | I48: 46061.833 | J48: 46068.833 | K48: =IF(OR(I48="",J48=""),"",IF(AND(J48<>"",I48>=NOW()),"Planned",IF(AND(J48<>"",J48<NOW()),"Completed","Ongoing"))) -> Planned | L48: 0.25 | N48: =IF(ISBLANK(L48),"",L48*VLOOKUP($F48,Internal!$B$26:$C$32,2,FALSE)) -> 7.5 | O48: =IF(ISBLANK(M48),"",M48*VLOOKUP($F48,Internal!$B$26:$C$32,2,FALSE))
B49: 39 | C49: =IF(ISBLANK(D49),"",_xlfn.CONCAT("T",TEXT(B49,"0000"),"/",VLOOKUP(D49,Internal!$B$35:C$39,2,FALSE),IF(OR(D49="QA",D49="Revision"),_xlfn.CONCAT("/",H49),""))) -> T0039/D | D49: Development | E49: Student 1 | F49: Developer | G49: Implement feature | I49: 46061.833 | J49: 46068.833 | K49: =IF(OR(I49="",J49=""),"",IF(AND(J49<>"",I49>=NOW()),"Planned",IF(AND(J49<>"",J49<NOW()),"Completed","Ongoing"))) -> Planned | L49: 0.5 | N49: =IF(ISBLANK(L49),"",L49*VLOOKUP($F49,Internal!$B$26:$C$32,2,FALSE)) -> 12.5 | O49: =IF(ISBLANK(M49),"",M49*VLOOKUP($F49,Internal!$B$26:$C$32,2,FALSE)) | P49: Testing: producir datos para comprobar los requisitos. Tienen que haber tres cuentas con rol de inventor y la última de ellas sin ningun dato asociado aparte de la información de perfil y su rol
B50: 40 | C50: =IF(ISBLANK(D50),"",_xlfn.CONCAT("T",TEXT(B50,"0000"),"/",VLOOKUP(D50,Internal!$B$35:C$39,2,FALSE),IF(OR(D50="QA",D50="Revision"),_xlfn.CONCAT("/",H50),""))) -> T0040/R/T0039/D | D50: Revision | E50: Student 2 | F50: Tester | G50: Check task | H50: T0039/D | I50: 46061.833 | J50: 46068.833 | K50: =IF(OR(I50="",J50=""),"",IF(AND(J50<>"",I50>=NOW()),"Planned",IF(AND(J50<>"",J50<NOW()),"Completed","Ongoing"))) -> Planned | L50: 0.25 | N50: =IF(ISBLANK(L50),"",L50*VLOOKUP($F50,Internal!$B$26:$C$32,2,FALSE)) -> 7.5 | O50: =IF(ISBLANK(M50),"",M50*VLOOKUP($F50,Internal!$B$26:$C$32,2,FALSE))
B51: 41 | C51: =IF(ISBLANK(D51),"",_xlfn.CONCAT("T",TEXT(B51,"0000"),"/",VLOOKUP(D51,Internal!$B$35:C$39,2,FALSE),IF(OR(D51="QA",D51="Revision"),_xlfn.CONCAT("/",H51),""))) -> T0041/D | D51: Development | E51: Student 2 | F51: Developer | G51: Implement feature | I51: 46061.833 | J51: 46068.833 | K51: =IF(OR(I51="",J51=""),"",IF(AND(J51<>"",I51>=NOW()),"Planned",IF(AND(J51<>"",J51<NOW()),"Completed","Ongoing"))) -> Planned | L51: 1 | N51: =IF(ISBLANK(L51),"",L51*VLOOKUP($F51,Internal!$B$26:$C$32,2,FALSE)) -> 25 | O51: =IF(ISBLANK(M51),"",M51*VLOOKUP($F51,Internal!$B$26:$C$32,2,FALSE)) | P51: Requisito de información: Implementar Model-C02.uxf
B52: 42 | C52: =IF(ISBLANK(D52),"",_xlfn.CONCAT("T",TEXT(B52,"0000"),"/",VLOOKUP(D52,Internal!$B$35:C$39,2,FALSE),IF(OR(D52="QA",D52="Revision"),_xlfn.CONCAT("/",H52),""))) -> T0042/R/T0041/D | D52: Revision | E52: Student 3 | F52: Tester | G52: Check task | H52: T0041/D | I52: 46061.833 | J52: 46068.833 | K52: =IF(OR(I52="",J52=""),"",IF(AND(J52<>"",I52>=NOW()),"Planned",IF(AND(J52<>"",J52<NOW()),"Completed","Ongoing"))) -> Planned | L52: 0.25 | N52: =IF(ISBLANK(L52),"",L52*VLOOKUP($F52,Internal!$B$26:$C$32,2,FALSE)) -> 7.5 | O52: =IF(ISBLANK(M52),"",M52*VLOOKUP($F52,Internal!$B$26:$C$32,2,FALSE))
B53: 43 | C53: =IF(ISBLANK(D53),"",_xlfn.CONCAT("T",TEXT(B53,"0000"),"/",VLOOKUP(D53,Internal!$B$35:C$39,2,FALSE),IF(OR(D53="QA",D53="Revision"),_xlfn.CONCAT("/",H53),""))) -> T0043/D | D53: Development | E53: Student 2 | F53: Developer | G53: Implement feature | I53: 46061.833 | J53: 46068.833 | K53: =IF(OR(I53="",J53=""),"",IF(AND(J53<>"",I53>=NOW()),"Planned",IF(AND(J53<>"",J53<NOW()),"Completed","Ongoing"))) -> Planned | L53: 1 | N53: =IF(ISBLANK(L53),"",L53*VLOOKUP($F53,Internal!$B$26:$C$32,2,FALSE)) -> 25 | O53: =IF(ISBLANK(M53),"",M53*VLOOKUP($F53,Internal!$B$26:$C$32,2,FALSE)) | P53: Funcional: Cualquier usuario podrá listar y mostrar las campañas publicadas y sus milestones. Además, de poder ver el perfil del portavoz
B54: 44 | C54: =IF(ISBLANK(D54),"",_xlfn.CONCAT("T",TEXT(B54,"0000"),"/",VLOOKUP(D54,Internal!$B$35:C$39,2,FALSE),IF(OR(D54="QA",D54="Revision"),_xlfn.CONCAT("/",H54),""))) -> T0044/R/T0043/D | D54: Revision | E54: Student 3 | F54: Tester | G54: Check task | H54: T0043/D | I54: 46061.833 | J54: 46068.833 | K54: =IF(OR(I54="",J54=""),"",IF(AND(J54<>"",I54>=NOW()),"Planned",IF(AND(J54<>"",J54<NOW()),"Completed","Ongoing"))) -> Planned | L54: 0.25 | N54: =IF(ISBLANK(L54),"",L54*VLOOKUP($F54,Internal!$B$26:$C$32,2,FALSE)) -> 7.5 | O54: =IF(ISBLANK(M54),"",M54*VLOOKUP($F54,Internal!$B$26:$C$32,2,FALSE))
B55: 45 | C55: =IF(ISBLANK(D55),"",_xlfn.CONCAT("T",TEXT(B55,"0000"),"/",VLOOKUP(D55,Internal!$B$35:C$39,2,FALSE),IF(OR(D55="QA",D55="Revision"),_xlfn.CONCAT("/",H55),""))) -> T0045/D | D55: Development | E55: Student 2 | F55: Developer | G55: Implement feature | I55: 46061.833 | J55: 46068.833 | K55: =IF(OR(I55="",J55=""),"",IF(AND(J55<>"",I55>=NOW()),"Planned",IF(AND(J55<>"",J55<NOW()),"Completed","Ongoing"))) -> Planned | L55: 1 | N55: =IF(ISBLANK(L55),"",L55*VLOOKUP($F55,Internal!$B$26:$C$32,2,FALSE)) -> 25 | O55: =IF(ISBLANK(M55),"",M55*VLOOKUP($F55,Internal!$B$26:$C$32,2,FALSE)) | P55: Funcional: Cualquier usuario autenticado podrá adquirir el rol de portavoz y actualizar el rol de su perfil
B56: 46 | C56: =IF(ISBLANK(D56),"",_xlfn.CONCAT("T",TEXT(B56,"0000"),"/",VLOOKUP(D56,Internal!$B$35:C$39,2,FALSE),IF(OR(D56="QA",D56="Revision"),_xlfn.CONCAT("/",H56),""))) -> T0046/R/T0045/D | D56: Revision | E56: Student 3 | F56: Tester | G56: Check task | H56: T0045/D | I56: 46061.833 | J56: 46068.833 | K56: =IF(OR(I56="",J56=""),"",IF(AND(J56<>"",I56>=NOW()),"Planned",IF(AND(J56<>"",J56<NOW()),"Completed","Ongoing"))) -> Planned | L56: 0.25 | N56: =IF(ISBLANK(L56),"",L56*VLOOKUP($F56,Internal!$B$26:$C$32,2,FALSE)) -> 7.5 | O56: =IF(ISBLANK(M56),"",M56*VLOOKUP($F56,Internal!$B$26:$C$32,2,FALSE))
...

Sheet D02
C2: Deliverable D02
C4: Use this form to document the tasks that you perform in your projects. Please, review the colour code in the "Abstract" sheet. In the exceptional case that you need to perform more tasks than expected, add them at the end.
C6: Costs | D6: Expected: | E6: =SUM(N11:N110) -> 0
D7: Actual: | E7: =SUM(O11:O110) -> 0
I9: Execution period | L9: Workload (in hours) | N9: Costs (in EUR)
B10: ORDER | C10: ID | D10: Type | E10: Assignee | F10: Role | G10: Activity | H10: Parent | I10: Start moment | J10: End moment | K10: Status | L10: Expected | M10: Actual | N10: Expected | O10: Actual | P10: Description
B11: 1 | C11: =IF(ISBLANK(D11),"",_xlfn.CONCAT("T",TEXT(B11,"0000"),"/",VLOOKUP(D11,Internal!$B$35:C$39,2,FALSE),IF(OR(D11="QA",D11="Revision"),_xlfn.CONCAT("/",H11),""))) | K11: =IF(OR(I11="",J11=""),"",IF(AND(J11<>"",I11>=NOW()),"Planned",IF(AND(J11<>"",J11<NOW()),"Completed","Ongoing"))) | N11: =IF(ISBLANK(L11),"",L11*VLOOKUP($F11,Internal!$B$26:$C$32,2,FALSE)) | O11: =IF(ISBLANK(M11),"",M11*VLOOKUP($F11,Internal!$B$26:$C$32,2,FALSE))
B12: 2 | C12: =IF(ISBLANK(D12),"",_xlfn.CONCAT("T",TEXT(B12,"0000"),"/",VLOOKUP(D12,Internal!$B$35:C$39,2,FALSE),IF(OR(D12="QA",D12="Revision"),_xlfn.CONCAT("/",H12),""))) | K12: =IF(OR(I12="",J12=""),"",IF(AND(J12<>"",I12>=NOW()),"Planned",IF(AND(J12<>"",J12<NOW()),"Completed","Ongoing"))) | N12: =IF(ISBLANK(L12),"",L12*VLOOKUP($F12,Internal!$B$26:$C$32,2,FALSE)) | O12: =IF(ISBLANK(M12),"",M12*VLOOKUP($F12,Internal!$B$26:$C$32,2,FALSE))
B13: 3 | C13: =IF(ISBLANK(D13),"",_xlfn.CONCAT("T",TEXT(B13,"0000"),"/",VLOOKUP(D13,Internal!$B$35:C$39,2,FALSE),IF(OR(D13="QA",D13="Revision"),_xlfn.CONCAT("/",H13),""))) | K13: =IF(OR(I13="",J13=""),"",IF(AND(J13<>"",I13>=NOW()),"Planned",IF(AND(J13<>"",J13<NOW()),"Completed","Ongoing"))) | N13: =IF(ISBLANK(L13),"",L13*VLOOKUP($F13,Internal!$B$26:$C$32,2,FALSE)) | O13: =IF(ISBLANK(M13),"",M13*VLOOKUP($F13,Internal!$B$26:$C$32,2,FALSE))
B14: 4 | C14: =IF(ISBLANK(D14),"",_xlfn.CONCAT("T",TEXT(B14,"0000"),"/",VLOOKUP(D14,Internal!$B$35:C$39,2,FALSE),IF(OR(D14="QA",D14="Revision"),_xlfn.CONCAT("/",H14),""))) | K14: =IF(OR(I14="",J14=""),"",IF(AND(J14<>"",I14>=NOW()),"Planned",IF(AND(J14<>"",J14<NOW()),"Completed","Ongoing"))) | N14: =IF(ISBLANK(L14),"",L14*VLOOKUP($F14,Internal!$B$26:$C$32,2,FALSE)) | O14: =IF(ISBLANK(M14),"",M14*VLOOKUP($F14,Internal!$B$26:$C$32,2,FALSE))
B15: 5 | C15: =IF(ISBLANK(D15),"",_xlfn.CONCAT("T",TEXT(B15,"0000"),"/",VLOOKUP(D15,Internal!$B$35:C$39,2,FALSE),IF(OR(D15="QA",D15="Revision"),_xlfn.CONCAT("/",H15),""))) | K15: =IF(OR(I15="",J15=""),"",IF(AND(J15<>"",I15>=NOW()),"Planned",IF(AND(J15<>"",J15<NOW()),"Completed","Ongoing"))) | N15: =IF(ISBLANK(L15),"",L15*VLOOKUP($F15,Internal!$B$26:$C$32,2,FALSE)) | O15: =IF(ISBLANK(M15),"",M15*VLOOKUP($F15,Internal!$B$26:$C$32,2,FALSE))
B16: 6 | C16: =IF(ISBLANK(D16),"",_xlfn.CONCAT("T",TEXT(B16,"0000"),"/",VLOOKUP(D16,Internal!$B$35:C$39,2,FALSE),IF(OR(D16="QA",D16="Revision"),_xlfn.CONCAT("/",H16),""))) | K16: =IF(OR(I16="",J16=""),"",IF(AND(J16<>"",I16>=NOW()),"Planned",IF(AND(J16<>"",J16<NOW()),"Completed","Ongoing"))) | N16: =IF(ISBLANK(L16),"",L16*VLOOKUP($F16,Internal!$B$26:$C$32,2,FALSE)) | O16: =IF(ISBLANK(M16),"",M16*VLOOKUP($F16,Internal!$B$26:$C$32,2,FALSE))
B17: 7 | C17: =IF(ISBLANK(D17),"",_xlfn.CONCAT("T",TEXT(B17,"0000"),"/",VLOOKUP(D17,Internal!$B$35:C$39,2,FALSE),IF(OR(D17="QA",D17="Revision"),_xlfn.CONCAT("/",H17),""))) | K17: =IF(OR(I17="",J17=""),"",IF(AND(J17<>"",I17>=NOW()),"Planned",IF(AND(J17<>"",J17<NOW()),"Completed","Ongoing"))) | N17: =IF(ISBLANK(L17),"",L17*VLOOKUP($F17,Internal!$B$26:$C$32,2,FALSE)) | O17: =IF(ISBLANK(M17),"",M17*VLOOKUP($F17,Internal!$B$26:$C$32,2,FALSE))
B18: 8 | C18: =IF(ISBLANK(D18),"",_xlfn.CONCAT("T",TEXT(B18,"0000"),"/",VLOOKUP(D18,Internal!$B$35:C$39,2,FALSE),IF(OR(D18="QA",D18="Revision"),_xlfn.CONCAT("/",H18),""))) | K18: =IF(OR(I18="",J18=""),"",IF(AND(J18<>"",I18>=NOW()),"Planned",IF(AND(J18<>"",J18<NOW()),"Completed","Ongoing"))) | N18: =IF(ISBLANK(L18),"",L18*VLOOKUP($F18,Internal!$B$26:$C$32,2,FALSE)) | O18: =IF(ISBLANK(M18),"",M18*VLOOKUP($F18,Internal!$B$26:$C$32,2,FALSE))
B19: 9 | C19: =IF(ISBLANK(D19),"",_xlfn.CONCAT("T",TEXT(B19,"0000"),"/",VLOOKUP(D19,Internal!$B$35:C$39,2,FALSE),IF(OR(D19="QA",D19="Revision"),_xlfn.CONCAT("/",H19),""))) | K19: =IF(OR(I19="",J19=""),"",IF(AND(J19<>"",I19>=NOW()),"Planned",IF(AND(J19<>"",J19<NOW()),"Completed","Ongoing"))) | N19: =IF(ISBLANK(L19),"",L19*VLOOKUP($F19,Internal!$B$26:$C$32,2,FALSE)) | O19: =IF(ISBLANK(M19),"",M19*VLOOKUP($F19,Internal!$B$26:$C$32,2,FALSE))
B20: 10 | C20: =IF(ISBLANK(D20),"",_xlfn.CONCAT("T",TEXT(B20,"0000"),"/",VLOOKUP(D20,Internal!$B$35:C$39,2,FALSE),IF(OR(D20="QA",D20="Revision"),_xlfn.CONCAT("/",H20),""))) | K20: =IF(OR(I20="",J20=""),"",IF(AND(J20<>"",I20>=NOW()),"Planned",IF(AND(J20<>"",J20<NOW()),"Completed","Ongoing"))) | N20: =IF(ISBLANK(L20),"",L20*VLOOKUP($F20,Internal!$B$26:$C$32,2,FALSE)) | O20: =IF(ISBLANK(M20),"",M20*VLOOKUP($F20,Internal!$B$26:$C$32,2,FALSE))
B21: 11 | C21: =IF(ISBLANK(D21),"",_xlfn.CONCAT("T",TEXT(B21,"0000"),"/",VLOOKUP(D21,Internal!$B$35:C$39,2,FALSE),IF(OR(D21="QA",D21="Revision"),_xlfn.CONCAT("/",H21),""))) | K21: =IF(OR(I21="",J21=""),"",IF(AND(J21<>"",I21>=NOW()),"Planned",IF(AND(J21<>"",J21<NOW()),"Completed","Ongoing"))) | N21: =IF(ISBLANK(L21),"",L21*VLOOKUP($F21,Internal!$B$26:$C$32,2,FALSE)) | O21: =IF(ISBLANK(M21),"",M21*VLOOKUP($F21,Internal!$B$26:$C$32,2,FALSE))
B22: 12 | C22: =IF(ISBLANK(D22),"",_xlfn.CONCAT("T",TEXT(B22,"0000"),"/",VLOOKUP(D22,Internal!$B$35:C$39,2,FALSE),IF(OR(D22="QA",D22="Revision"),_xlfn.CONCAT("/",H22),""))) | K22: =IF(OR(I22="",J22=""),"",IF(AND(J22<>"",I22>=NOW()),"Planned",IF(AND(J22<>"",J22<NOW()),"Completed","Ongoing"))) | N22: =IF(ISBLANK(L22),"",L22*VLOOKUP($F22,Internal!$B$26:$C$32,2,FALSE)) | O22: =IF(ISBLANK(M22),"",M22*VLOOKUP($F22,Internal!$B$26:$C$32,2,FALSE))
... B110: 100 | C110: =IF(ISBLANK(D110),"",_xlfn.CONCAT("T",TEXT(B110,"0000"),"/",VLOOKUP(D110,Internal!$B$35:C$39,2,FALSE),IF(OR(D110="QA",D110="Revision"),_xlfn.CONCAT("/",H110),""))) | K110: =IF(OR(I110="",J110=""),"",IF(AND(J110<>"",I110>=NOW()),"Planned",IF(AND(J110<>"",J110<NOW()),"Completed","Ongoing"))) | N110: =IF(ISBLANK(L110),"",L110*VLOOKUP($F110,Internal!$B$26:$C$32,2,FALSE)) | O110: =IF(ISBLANK(M110),"",M110*VLOOKUP($F110,Internal!$B$26:$C$32,2,FALSE))

Sheet D03
C2: Deliverable D03
C4: Use this form to document the tasks that you perform in your projects. Please, review the colour code in the "Abstract" sheet. In the exceptional case that you need to perform more tasks than expected, add them at the end.
C6: Costs | D6: Expected: | E6: =SUM(N11:N110) -> 0
D7: Actual: | E7: =SUM(O11:O110) -> 0
I9: Execution period | L9: Workload (in hours) | N9: Costs (in EUR)
B10: ORDER | C10: ID | D10: Type | E10: Assignee | F10: Role | G10: Activity | H10: Parent | I10: Start moment | J10: End moment | K10: Status | L10: Expected | M10: Actual | N10: Expected | O10: Actual | P10: Description
B11: 1 | C11: =IF(ISBLANK(D11),"",_xlfn.CONCAT("T",TEXT(B11,"0000"),"/",VLOOKUP(D11,Internal!$B$35:C$39,2,FALSE),IF(OR(D11="QA",D11="Revision"),_xlfn.CONCAT("/",H11),""))) | K11: =IF(OR(I11="",J11=""),"",IF(AND(J11<>"",I11>=NOW()),"Planned",IF(AND(J11<>"",J11<NOW()),"Completed","Ongoing"))) | N11: =IF(ISBLANK(L11),"",L11*VLOOKUP($F11,Internal!$B$26:$C$32,2,FALSE)) | O11: =IF(ISBLANK(M11),"",M11*VLOOKUP($F11,Internal!$B$26:$C$32,2,FALSE))
B12: 2 | C12: =IF(ISBLANK(D12),"",_xlfn.CONCAT("T",TEXT(B12,"0000"),"/",VLOOKUP(D12,Internal!$B$35:C$39,2,FALSE),IF(OR(D12="QA",D12="Revision"),_xlfn.CONCAT("/",H12),""))) | K12: =IF(OR(I12="",J12=""),"",IF(AND(J12<>"",I12>=NOW()),"Planned",IF(AND(J12<>"",J12<NOW()),"Completed","Ongoing"))) | N12: =IF(ISBLANK(L12),"",L12*VLOOKUP($F12,Internal!$B$26:$C$32,2,FALSE)) | O12: =IF(ISBLANK(M12),"",M12*VLOOKUP($F12,Internal!$B$26:$C$32,2,FALSE))
B13: 3 | C13: =IF(ISBLANK(D13),"",_xlfn.CONCAT("T",TEXT(B13,"0000"),"/",VLOOKUP(D13,Internal!$B$35:C$39,2,FALSE),IF(OR(D13="QA",D13="Revision"),_xlfn.CONCAT("/",H13),""))) | K13: =IF(OR(I13="",J13=""),"",IF(AND(J13<>"",I13>=NOW()),"Planned",IF(AND(J13<>"",J13<NOW()),"Completed","Ongoing"))) | N13: =IF(ISBLANK(L13),"",L13*VLOOKUP($F13,Internal!$B$26:$C$32,2,FALSE)) | O13: =IF(ISBLANK(M13),"",M13*VLOOKUP($F13,Internal!$B$26:$C$32,2,FALSE))
B14: 4 | C14: =IF(ISBLANK(D14),"",_xlfn.CONCAT("T",TEXT(B14,"0000"),"/",VLOOKUP(D14,Internal!$B$35:C$39,2,FALSE),IF(OR(D14="QA",D14="Revision"),_xlfn.CONCAT("/",H14),""))) | K14: =IF(OR(I14="",J14=""),"",IF(AND(J14<>"",I14>=NOW()),"Planned",IF(AND(J14<>"",J14<NOW()),"Completed","Ongoing"))) | N14: =IF(ISBLANK(L14),"",L14*VLOOKUP($F14,Internal!$B$26:$C$32,2,FALSE)) | O14: =IF(ISBLANK(M14),"",M14*VLOOKUP($F14,Internal!$B$26:$C$32,2,FALSE))
B15: 5 | C15: =IF(ISBLANK(D15),"",_xlfn.CONCAT("T",TEXT(B15,"0000"),"/",VLOOKUP(D15,Internal!$B$35:C$39,2,FALSE),IF(OR(D15="QA",D15="Revision"),_xlfn.CONCAT("/",H15),""))) | K15: =IF(OR(I15="",J15=""),"",IF(AND(J15<>"",I15>=NOW()),"Planned",IF(AND(J15<>"",J15<NOW()),"Completed","Ongoing"))) | N15: =IF(ISBLANK(L15),"",L15*VLOOKUP($F15,Internal!$B$26:$C$32,2,FALSE)) | O15: =IF(ISBLANK(M15),"",M15*VLOOKUP($F15,Internal!$B$26:$C$32,2,FALSE))
B16: 6 | C16: =IF(ISBLANK(D16),"",_xlfn.CONCAT("T",TEXT(B16,"0000"),"/",VLOOKUP(D16,Internal!$B$35:C$39,2,FALSE),IF(OR(D16="QA",D16="Revision"),_xlfn.CONCAT("/",H16),""))) | K16: =IF(OR(I16="",J16=""),"",IF(AND(J16<>"",I16>=NOW()),"Planned",IF(AND(J16<>"",J16<NOW()),"Completed","Ongoing"))) | N16: =IF(ISBLANK(L16),"",L16*VLOOKUP($F16,Internal!$B$26:$C$32,2,FALSE)) | O16: =IF(ISBLANK(M16),"",M16*VLOOKUP($F16,Internal!$B$26:$C$32,2,FALSE))
B17: 7 | C17: =IF(ISBLANK(D17),"",_xlfn.CONCAT("T",TEXT(B17,"0000"),"/",VLOOKUP(D17,Internal!$B$35:C$39,2,FALSE),IF(OR(D17="QA",D17="Revision"),_xlfn.CONCAT("/",H17),""))) | K17: =IF(OR(I17="",J17=""),"",IF(AND(J17<>"",I17>=NOW()),"Planned",IF(AND(J17<>"",J17<NOW()),"Completed","Ongoing"))) | N17: =IF(ISBLANK(L17),"",L17*VLOOKUP($F17,Internal!$B$26:$C$32,2,FALSE)) | O17: =IF(ISBLANK(M17),"",M17*VLOOKUP($F17,Internal!$B$26:$C$32,2,FALSE))
B18: 8 | C18: =IF(ISBLANK(D18),"",_xlfn.CONCAT("T",TEXT(B18,"0000"),"/",VLOOKUP(D18,Internal!$B$35:C$39,2,FALSE),IF(OR(D18="QA",D18="Revision"),_xlfn.CONCAT("/",H18),""))) | K18: =IF(OR(I18="",J18=""),"",IF(AND(J18<>"",I18>=NOW()),"Planned",IF(AND(J18<>"",J18<NOW()),"Completed","Ongoing"))) | N18: =IF(ISBLANK(L18),"",L18*VLOOKUP($F18,Internal!$B$26:$C$32,2,FALSE)) | O18: =IF(ISBLANK(M18),"",M18*VLOOKUP($F18,Internal!$B$26:$C$32,2,FALSE))
B19: 9 | C19: =IF(ISBLANK(D19),"",_xlfn.CONCAT("T",TEXT(B19,"0000"),"/",VLOOKUP(D19,Internal!$B$35:C$39,2,FALSE),IF(OR(D19="QA",D19="Revision"),_xlfn.CONCAT("/",H19),""))) | K19: =IF(OR(I19="",J19=""),"",IF(AND(J19<>"",I19>=NOW()),"Planned",IF(AND(J19<>"",J19<NOW()),"Completed","Ongoing"))) | N19: =IF(ISBLANK(L19),"",L19*VLOOKUP($F19,Internal!$B$26:$C$32,2,FALSE)) | O19: =IF(ISBLANK(M19),"",M19*VLOOKUP($F19,Internal!$B$26:$C$32,2,FALSE))
B20: 10 | C20: =IF(ISBLANK(D20),"",_xlfn.CONCAT("T",TEXT(B20,"0000"),"/",VLOOKUP(D20,Internal!$B$35:C$39,2,FALSE),IF(OR(D20="QA",D20="Revision"),_xlfn.CONCAT("/",H20),""))) | K20: =IF(OR(I20="",J20=""),"",IF(AND(J20<>"",I20>=NOW()),"Planned",IF(AND(J20<>"",J20<NOW()),"Completed","Ongoing"))) | N20: =IF(ISBLANK(L20),"",L20*VLOOKUP($F20,Internal!$B$26:$C$32,2,FALSE)) | O20: =IF(ISBLANK(M20),"",M20*VLOOKUP($F20,Internal!$B$26:$C$32,2,FALSE))
B21: 11 | C21: =IF(ISBLANK(D21),"",_xlfn.CONCAT("T",TEXT(B21,"0000"),"/",VLOOKUP(D21,Internal!$B$35:C$39,2,FALSE),IF(OR(D21="QA",D21="Revision"),_xlfn.CONCAT("/",H21),""))) | K21: =IF(OR(I21="",J21=""),"",IF(AND(J21<>"",I21>=NOW()),"Planned",IF(AND(J21<>"",J21<NOW()),"Completed","Ongoing"))) | N21: =IF(ISBLANK(L21),"",L21*VLOOKUP($F21,Internal!$B$26:$C$32,2,FALSE)) | O21: =IF(ISBLANK(M21),"",M21*VLOOKUP($F21,Internal!$B$26:$C$32,2,FALSE))
B22: 12 | C22: =IF(ISBLANK(D22),"",_xlfn.CONCAT("T",TEXT(B22,"0000"),"/",VLOOKUP(D22,Internal!$B$35:C$39,2,FALSE),IF(OR(D22="QA",D22="Revision"),_xlfn.CONCAT("/",H22),""))) | K22: =IF(OR(I22="",J22=""),"",IF(AND(J22<>"",I22>=NOW()),"Planned",IF(AND(J22<>"",J22<NOW()),"Completed","Ongoing"))) | N22: =IF(ISBLANK(L22),"",L22*VLOOKUP($F22,Internal!$B$26:$C$32,2,FALSE)) | O22: =IF(ISBLANK(M22),"",M22*VLOOKUP($F22,Internal!$B$26:$C$32,2,FALSE))
... B110: 100 | C110: =IF(ISBLANK(D110),"",_xlfn.CONCAT("T",TEXT(B110,"0000"),"/",VLOOKUP(D110,Internal!$B$35:C$39,2,FALSE),IF(OR(D110="QA",D110="Revision"),_xlfn.CONCAT("/",H110),""))) | K110: =IF(OR(I110="",J110=""),"",IF(AND(J110<>"",I110>=NOW()),"Planned",IF(AND(J110<>"",J110<NOW()),"Completed","Ongoing"))) | N110: =IF(ISBLANK(L110),"",L110*VLOOKUP($F110,Internal!$B$26:$C$32,2,FALSE)) | O110: =IF(ISBLANK(M110),"",M110*VLOOKUP($F110,Internal!$B$26:$C$32,2,FALSE))

Sheet Internal
B2: Internal data
B4: This sheet contains internal data that are used elsewhere to perform some checks and computations. Please, do not modify it al all.
B8: Prospective assignees
B9: Student 1
B10: Student 2
B11: Student 3
B12: Student 4
B13: Student 5
B14: ALL
B16: Statuses
B17: Planned
B18: Ongoing
... B21: Moments
B22: 45658
B23: 2100/31/12 23:59:59
B25: Roles | C25: Cost | D25: Tasks…
B26: Student | C26: 0 | D26: Attend lecture | E26: Study and train | F26: Attend work meeting | G26: Other (Describe)
B27: Manager | C27: 50 | D27: Make plans | E27: Make re-plannings | F27: Initialise repository | G27: Supervise task | H27: Write report | I27: Other (Describe)
B28: Analyst | C28: 40 | D28: Elicit requirements | E28: Define features | F28: Create domain model | G28: Write report | H28: Other (Describe)
B29: Developer | C29: 25 | D29: Create dev. config. | E29: Customise the starter | F29: Implement feature | G29: Test feature informally | H29: Write report | I29: Other (Describe)
B30: Tester | C30: 30 | D30: Check deliverable | E30: Check task | F30: Test feature formally | G30: Test performance formally | H30: Write report | I30: Other (Describe)
B31: Operator | C31: 30 | D31: Prepare dep. platf. | E31: Package deliverable | F31: Upload deliverable | G31: Deploy application | H31: Keep application running | I31: Write report | J31: Other (Describe)
B32: Other | C32: 10 | D32: Other (Describe)
B34: Task types | C34: Key
B35: Management | C35: M
B36: Development | C36: D
B37: QA | C37: QA
B38: Revision | C38: R
B39: Other | C39: O
